{"errorMessage":"Lambda process returned with error. Result: . Output:\n","errorType":"InvocationException","stackTrace":["  File \"/opt/code/localstack/localstack/services/awslambda/lambda_api.py\", line 820, in run_lambda\n    lock_discriminator=lock_discriminator,\n","  File \"/opt/code/localstack/localstack/services/awslambda/lambda_executors.py\", line 399, in execute\n    return do_execute()\n","  File \"/opt/code/localstack/localstack/services/awslambda/lambda_executors.py\", line 389, in do_execute\n    return _run(func_arn=func_arn)\n","  File \"/opt/code/localstack/localstack/utils/cloudwatch/cloudwatch_util.py\", line 157, in wrapped\n    raise e\n","  File \"/opt/code/localstack/localstack/utils/cloudwatch/cloudwatch_util.py\", line 153, in wrapped\n    result = func(*args, **kwargs)\n","  File \"/opt/code/localstack/localstack/services/awslambda/lambda_executors.py\", line 376, in _run\n    raise e\n","  File \"/opt/code/localstack/localstack/services/awslambda/lambda_executors.py\", line 362, in _run\n    result = self._execute(lambda_function, inv_context)\n","  File \"/opt/code/localstack/localstack/services/awslambda/lambda_executors.py\", line 659, in _execute\n    result = self.run_lambda_executor(lambda_function=lambda_function, inv_context=inv_context)\n","  File \"/opt/code/localstack/localstack/services/awslambda/lambda_executors.py\", line 587, in run_lambda_executor\n    ) from error\n"]}
